Workbook

Sheet Checklist
B1: FY18 | C1: FY19 | D1: FY20 | E1: FY21 | F1: FY22 | G1: FY23 | H1: FY24 | I1: FY25 | J1: FY26
A2: JAC | F2: x | G2: o | I2: x | M2: To-dos:
A3: CDPH
A4: OFVP | B4: - | C4: - | D4: - | E4: - | F4: x | G4: x | H4: x | I4: x
A5: ICJIA | C5: x | D5: x | E5: x | F5: x | G5: x | H5: x | I5: x
A6: Private? | B6: CRED + PSPC (to CP4P) + SC2
A7: Federal?
A11: Jack | B11: Erin | C11: Jack | D11: Jack
A12: ICJIA | B12: OFVP | C12: JAC | D12: CDPH
A13: Done | B13: Done | C13: Cleaning | D13: Outreach

Sheet Private funding
A1: Private CVI direct programming funding
A3: SC2 - direct CVI programming investments (scaling). Source: SC2 Cash Flow Tracker, Oct 2025
B4: FY22 | C4: FY23 | D4: FY24 | E4: FY25 | F4: FY26 (budgeted) | G4: FY24-26 total
A5: North Lawndale | D5: 0 | E5: 4755519 | F5: 5919882 | G5: =SUM(D5:F5) -> 10675401
A6: Austin | D6: 346759 | E6: 4314101 | F6: 6497838 | G6: =SUM(D6:F6) -> 11158698
A7: Humboldt Park | D7: 422000 | E7: 4341756 | F7: 6834298 | G7: =SUM(D7:F7) -> 11598054
A8: Garfield Park | D8: 311938 | E8: 978512 | F8: 1000004 | G8: =SUM(D8:F8) -> 2290454
A9: Englewood | D9: 202400 | E9: 109250 | F9: 0 | G9: =SUM(D9:F9) -> 311650
A10: New City | D10: 0 | E10: 140510 | F10: 0 | G10: =SUM(D10:F10) -> 140510
A11: South Lawndale | D11: 257610 | E11: 1357934 | F11: 5835343 | G11: =SUM(D11:F11) -> 7450887
A12: Total | D12: =SUM(D5:D11) -> 1540707 | E12: =SUM(E5:E11) -> 15997582 | F12: =SUM(F5:F11) -> 26087365 | G12: =SUM(D12:F12) -> 43625654
A15: CRED - direct CVI programming investments (Baseline). Source: Jen Keeling, Oct. 2025
B16: FY22 | C16: FY23 | D16: FY24 | E16: FY25 | F16: FY26 (budgeted) | G16: FY22-26 total
A17: North Lawndale | B17: 6856474 | C17: 7068502 | D17: 8231858 | E17: 7298126 | F17: 7298126 | G17: =SUM(B17:F17) -> 36753086
A18: Austin | B18: 365000 | C18: 383250 | D18: 402413 | E18: 570545 | F18: 543375 | G18: =SUM(B18:F18) -> 2264583
A19: Humboldt Park | B19: 350000 | C19: 367500 | D19: 385875 | E19: 385875 | F19: 475875 | G19: =SUM(B19:F19) -> 1965125
A20: South Lawndale | B20: 0 | C20: 0 | D20: 0 | E20: 0 | F20: 0 | G20: =SUM(B20:F20) -> 0
A21: West Garfield Park | B21: 325000 | C21: 341250 | D21: 358313 | E21: 490182 | F21: 331125 | G21: =SUM(B21:F21) -> 1845870
A22: West Englewood | B22: 0 | C22: 0 | D22: 0 | E22: 0 | F22: 0 | G22: =SUM(B22:F22) -> 0
A23: Roseland | B23: 8807840 | C23: 9136270 | D23: 10092718 | E23: 11126084 | F23: 11126084 | G23: =SUM(B23:F23) -> 50288996
A24: Auburn Gresham | B24: 465000 | C24: 488250 | D24: 512663 | E24: 512663 | F24: 410000 | G24: =SUM(B24:F24) -> 2388576
A25: Englewood | B25: 0 | C25: 0 | D25: 0 | E25: 300000 | F25: 150000 | G25: =SUM(B25:F25) -> 450000
A26: Woodlawn | B26: 200000 | C26: 210000 | D26: 220500 | E26: 220500 | F26: 210000 | G26: =SUM(B26:F26) -> 1061000
A27: Washington Park | B27: 200000 | C27: 210000 | D27: 220500 | E27: 220500 | F27: 210000 | G27: =SUM(B27:F27) -> 1061000
A28: Total | B28: =SUM(B17:B27) -> 17569314 | C28: =SUM(C17:C27) -> 18205022 | D28: =SUM(D17:D27) -> 20424840 | E28: =SUM(E17:E27) -> 21124475 | F28: =SUM(F17:F27) -> 20754585 | G28: =SUM(B28:F28) -> 98078236
A31: CP4P (via PSPC) - private funding, excluding CRED direct funding. Source: Leticia Reyes, Summer 2025
B32: FY22 | C32: FY23 | D32: FY24 | E32: FY25 | F32: FY22-25 total
A33: Albany Park | B33: 25000 | C33: 25000 | D33: 25000 | E33: 25000 | F33: =SUM(B33:E33) -> 100000
A34: Auburn Gresham | B34: 200000 | C34: 200000 | D34: 25000 | E34: 25000 | F34: =SUM(B34:E34) -> 450000
A35: Austin | B35: 200000 | C35: 200000 | D35: 3275920 | E35: 1467562 | F35: =SUM(B35:E35) -> 5143482
A36: Avondale | B36: 25000 | C36: 25000 | D36: 25000 | E36: 25000 | F36: =SUM(B36:E36) -> 100000
A37: Belmont-Cragin | B37: 25000 | C37: 25000 | D37: 25000 | E37: 25000 | F37: =SUM(B37:E37) -> 100000
A38: Brighton Park | B38: 25000 | C38: 115000 | D38: 25000 | E38: 25000 | F38: =SUM(B38:E38) -> 190000
A39: Burnside | B39: 0 | C39: 0 | D39: 0 | E39: 0 | F39: =SUM(B39:E39) -> 0
A40: Chatham | B40: 25000 | C40: 25000 | D40: 25000 | E40: 25000 | F40: =SUM(B40:E40) -> 100000
A41: Chicago Lawn | B41: 25000 | C41: 25000 | D41: 25000 | E41: 25000 | F41: =SUM(B41:E41) -> 100000
A42: West Garfield Park | B42: 300000 | C42: 200000 | D42: 200000 | E42: 1474710 | F42: =SUM(B42:E42) -> 2174710
A43: East Garfield Park | B43: 300000 | C43: 280000 | D43: 200000 | E43: 200000 | F43: =SUM(B43:E43) -> 980000
A44: West Englewood | B44: 200000 | C44: 150000 | D44: 200000 | E44: 175000 | F44: =SUM(B44:E44) -> 725000
... A73: Citywide Services | B73: 7955000 | C73: 1456707 | D73: 2417265 | E73: 1833438 | F73: =SUM(B73:E73) -> 13662410
...

Sheet OFVP Pivot
B4: Sum of Award Amount | C4: Column Labels
B5: Row Labels | C5: 2022 | D5: 2023 | E5: 2024 | F5: 2025 | G5: 2026 | H5: Grand Total
B6: Austin | C6: 368008.5 | D6: 3243146.1 | E6: 4282570 | F6: 4056668 | G6: 3948867 | H6: 15899260
B7: North Lawndale | C7: 249615 | D7: 2526283 | E7: 4525577 | F7: 4152894 | G7: 4197282 | H7: 15651651
B8: Greater Grand Crossing | C8: 162275 | D8: 1509810 | E8: 4025178 | F8: 2713061 | G8: 2537021 | H8: 10947345
B9: West Garfield Park | C9: 290751.5 | D9: 2027136.8 | E9: 2978877 | F9: 2775154 | G9: 2846582 | H9: 10918501
B10: Humboldt Park | C10: 219429 | D10: 2624859 | E10: 4087477 | F10: 2304355 | G10: 1659225 | H10: 10895345
B11: South Lawndale | C11: 286540 | D11: 1705603 | E11: 2807169 | F11: 2981801 | G11: 2837967 | H11: 10619080
B12: Waukegan-North Chicago Cluster | D12: 1646824 | E12: 4110198.7 | F12: 2585969 | G12: 2216619 | H12: 10559611
B13: Auburn Gresham | C13: 86426.95 | D13: 1371996 | E13: 3126557 | F13: 2846666 | G13: 2540591 | H13: 9972236.9
B14: East Garfield Park | C14: 174073 | D14: 1487871.6 | E14: 3166690 | F14: 2566849 | G14: 2320548 | H14: 9716031.6
B15: Roseland | C15: 260647 | D15: 879788 | E15: 3060867 | F15: 2632062 | G15: 2814947 | H15: 9648311
B16: West Pullman | C16: 281714 | D16: 1213036.2 | E16: 3196757 | F16: 2372775 | G16: 1732503 | H16: 8796785.2
B17: Englewood | C17: 181355.95 | D17: 1283982 | E17: 3334227 | F17: 2268966 | G17: 1589516 | H17: 8658046.9
B18: Northside Cluster | D18: 781929 | E18: 2364830 | F18: 2654250 | G18: 2722987 | H18: 8523996
B19: West Englewood | C19: 155616 | D19: 889277 | E19: 2451063.4 | F19: 2403518 | G19: 2393516 | H19: 8292990.4
B20: Calumet City Cluster | C20: 25433 | D20: 1244387 | E20: 2945687 | F20: 2360737 | G20: 1548299 | H20: 8124543
B21: Joliet | C21: 18088 | D21: 767373 | E21: 2949966 | F21: 2364873 | G21: 1916338 | H21: 8016638
B22: Chatham | C22: 82829 | D22: 757322 | E22: 1998951 | F22: 2338695 | G22: 2658224 | H22: 7836021
B23: South Shore | C23: 147706 | D23: 1118403 | E23: 2399492 | F23: 2039976 | G23: 1593498 | H23: 7299075
B24: Rockford | C24: 12396 | D24: 1226856 | E24: 2359764 | F24: 2211589 | G24: 1194966 | H24: 7005571
B25: Berwyn-Cicero Cluster | C25: 64692 | D25: 1118643 | E25: 1762665 | F25: 1765429 | G25: 1986323 | H25: 6697752
B26: Southwest Side Cluster | D26: 386932 | E26: 1485954 | F26: 2081653 | G26: 2630107 | H26: 6584646
B27: New City | C27: 108520 | D27: 1247834 | E27: 1858458 | F27: 1684415 | G27: 1251244 | H27: 6150471
B28: Aurora | C28: 25466 | D28: 779208 | E28: 2246833 | F28: 1630078 | G28: 1340443 | H28: 6022028
B29: Belleville Cluster | D29: 372781 | E29: 1695312.6 | F29: 1952934 | G29: 1961218 | H29: 5982245.6
B30: South Chicago | C30: 225743 | D30: 1024249 | E30: 1610049 | F30: 1516973 | G30: 1432328 | H30: 5809342
B31: Washington Park | C31: 111833 | D31: 747263 | E31: 1985595 | F31: 1209527 | G31: 1038408 | H31: 5092626
B32: Chicago Lawn | C32: 127575 | D32: 567296 | E32: 1140074 | F32: 1536640 | G32: 1673201 | H32: 5044786
B33: Woodlawn | C33: 275845 | D33: 936447 | E33: 1742882 | F33: 1167460 | G33: 749641 | H33: 4872275
B34: Riverdale | C34: 63385 | D34: 650406 | E34: 1347956 | F34: 1336839 | G34: 1390546 | H34: 4789132
B35: Fuller Park | C35: 75000 | D35: 400000 | E35: 1394548 | F35: 1497250 | G35: 1134948 | H35: 4501746
B36: Peoria | C36: 24110 | D36: 424759 | E36: 1183549 | F36: 1099154 | G36: 1500534 | H36: 4232106
B37: Decatur | C37: 51083 | D37: 477857 | E37: 1207340 | F37: 866770 | G37: 1217281 | H37: 3820331
B38: Kankakee | D38: 459111 | E38: 1170816 | F38: 1082339 | G38: 889260 | H38: 3601526
B39: Chicago Heights Cluster | D39: 171357 | E39: 892001 | F39: 1054490 | G39: 1254968 | H39: 3372816
B40: Rock Island | D40: 509171 | E40: 592397 | F40: 793059 | G40: 1207432 | H40: 3102059
B41: Urbana-Champaign Cluster | C41: 42750 | D41: 427857 | E41: 979843 | F41: 635083 | G41: 900434 | H41: 2985967
B42: Burnside | D42: 132298.64 | E42: 934020 | F42: 1012419 | G42: 868837 | H42: 2947574.6
B43: Maywood-Bellwood Cluster | D43: 134191 | E43: 385809 | F43: 869084 | G43: 1299700 | H43: 2688784
...

Sheet OFVP
A1: Source | B1: Grant Type | C1: Award ID | D1: CSFA | E1: Grantee Name | F1: Start Date | G1: End Date | H1: Award Amount | I1: Fiscal Year | J1: Chicago/Greater Illinois | K1: County | L1: Community Area | M1: CVI | N1: FLIP | O1: CP4P | P1: SC2o | Q1: SC2c
A2: =IF(ISBLANK(E2),"","OFVP") -> OFVP | B2: TA Services Violence Prevention | D2: 2771 | E2: Acclivus, Inc. | G2: 45930 | H2: 150000 | I2: 2022 | J2: Chicago | K2: Cook | L2: z TTAS - Chicago | M2: =IF(ISNUMBER(MATCH(E2,_xlfn.VSTACK('VLookup Lists'!$E$2:$E$17,'VLookup Lists'!$H$2:$H$38,'VLookup Lists'!$J$2:$J$8),0)),1,0) -> 1 | N2: =IFERROR(IF(VLOOKUP($D2,'VLookup Lists'!$B$11:$C$29,2,FALSE)="FLIP",1,0),"") -> 0 | O2: =ISNUMBER(MATCH($E2,'VLookup Lists'!$E$2:$E$17,0)) -> FALSE
A3: =IF(ISBLANK(E3),"","OFVP") -> OFVP | B3: TA Services Violence Prevention | D3: 2771 | E3: Metropolitan Family Services | G3: 45565 | H3: 188061 | I3: 2022 | J3: Chicago | K3: Cook | L3: z TTAS - Chicago | M3: =IF(ISNUMBER(MATCH(E3,_xlfn.VSTACK('VLookup Lists'!$E$2:$E$17,'VLookup Lists'!$H$2:$H$38,'VLookup Lists'!$J$2:$J$8),0)),1,0) -> 1 | N3: =IFERROR(IF(VLOOKUP($D3,'VLookup Lists'!$B$11:$C$29,2,FALSE)="FLIP",1,0),"") -> 0 | O3: =ISNUMBER(MATCH($E3,'VLookup Lists'!$E$2:$E$17,0)) -> TRUE
A4: =IF(ISBLANK(E4),"","OFVP") -> OFVP | B4: TA Services Violence Prevention | D4: 2771 | E4: UNIVERSAL FAMILY CONNECTION | G4: 45344 | H4: 159600 | I4: 2022 | J4: Chicago | K4: Cook | L4: z TTAS - Chicago | M4: =IF(ISNUMBER(MATCH(E4,_xlfn.VSTACK('VLookup Lists'!$E$2:$E$17,'VLookup Lists'!$H$2:$H$38,'VLookup Lists'!$J$2:$J$8),0)),1,0) -> 0 | N4: =IFERROR(IF(VLOOKUP($D4,'VLookup Lists'!$B$11:$C$29,2,FALSE)="FLIP",1,0),"") -> 0 | O4: =ISNUMBER(MATCH($E4,'VLookup Lists'!$E$2:$E$17,0)) -> FALSE
A5: =IF(ISBLANK(E5),"","OFVP") -> OFVP | B5: TA Services Youth Development | D5: 2772 | E5: BLACK COMMUNITY PROVIDER | G5: 45565 | H5: 145486 | I5: 2022 | J5: Chicago | K5: Cook | L5: z TTAS - Chicago | M5: =IF(ISNUMBER(MATCH(E5,_xlfn.VSTACK('VLookup Lists'!$E$2:$E$17,'VLookup Lists'!$H$2:$H$38,'VLookup Lists'!$J$2:$J$8),0)),1,0) -> 0 | N5: =IFERROR(IF(VLOOKUP($D5,'VLookup Lists'!$B$11:$C$29,2,FALSE)="FLIP",1,0),"") -> 0 | O5: =ISNUMBER(MATCH($E5,'VLookup Lists'!$E$2:$E$17,0)) -> FALSE
A6: =IF(ISBLANK(E6),"","OFVP") -> OFVP | B6: TA Services Youth Development | D6: 2772 | E6: Metropolitan Family Services | G6: 45565 | H6: 203463 | I6: 2022 | J6: Chicago | K6: Cook | L6: z TTAS - Chicago | M6: =IF(ISNUMBER(MATCH(E6,_xlfn.VSTACK('VLookup Lists'!$E$2:$E$17,'VLookup Lists'!$H$2:$H$38,'VLookup Lists'!$J$2:$J$8),0)),1,0) -> 1 | N6: =IFERROR(IF(VLOOKUP($D6,'VLookup Lists'!$B$11:$C$29,2,FALSE)="FLIP",1,0),"") -> 0 | O6: =ISNUMBER(MATCH($E6,'VLookup Lists'!$E$2:$E$17,0)) -> TRUE
A7: =IF(ISBLANK(E7),"","OFVP") -> OFVP | B7: TA Services Youth Development | D7: 2772 | E7: Prevention First, Inc | G7: 45565 | H7: 168150 | I7: 2022 | J7: Chicago | K7: Cook | L7: z TTAS - Chicago | M7: =IF(ISNUMBER(MATCH(E7,_xlfn.VSTACK('VLookup Lists'!$E$2:$E$17,'VLookup Lists'!$H$2:$H$38,'VLookup Lists'!$J$2:$J$8),0)),1,0) -> 0 | N7: =IFERROR(IF(VLOOKUP($D7,'VLookup Lists'!$B$11:$C$29,2,FALSE)="FLIP",1,0),"") -> 0 | O7: =ISNUMBER(MATCH($E7,'VLookup Lists'!$E$2:$E$17,0)) -> FALSE
A8: =IF(ISBLANK(E8),"","OFVP") -> OFVP | B8: Chicago Conveners | D8: 2773 | E8: Lawrence Hall Youth Services | G8: 45747 | H8: 25000 | I8: 2022 | J8: Chicago | K8: Cook | L8: South Shore | M8: =IF(ISNUMBER(MATCH(E8,_xlfn.VSTACK('VLookup Lists'!$E$2:$E$17,'VLookup Lists'!$H$2:$H$38,'VLookup Lists'!$J$2:$J$8),0)),1,0) -> 0 | N8: =IFERROR(IF(VLOOKUP($D8,'VLookup Lists'!$B$11:$C$29,2,FALSE)="FLIP",1,0),"") -> 0 | O8: =ISNUMBER(MATCH($E8,'VLookup Lists'!$E$2:$E$17,0)) -> FALSE
A9: =IF(ISBLANK(E9),"","OFVP") -> OFVP | B9: Chicago Conveners | D9: 2773 | E9: UNIVERSAL FAMILY CONNECTION | G9: 45747 | H9: 24999.95 | I9: 2022 | J9: Chicago | K9: Cook | L9: Auburn Gresham | M9: =IF(ISNUMBER(MATCH(E9,_xlfn.VSTACK('VLookup Lists'!$E$2:$E$17,'VLookup Lists'!$H$2:$H$38,'VLookup Lists'!$J$2:$J$8),0)),1,0) -> 0 | N9: =IFERROR(IF(VLOOKUP($D9,'VLookup Lists'!$B$11:$C$29,2,FALSE)="FLIP",1,0),"") -> 0 | O9: =ISNUMBER(MATCH($E9,'VLookup Lists'!$E$2:$E$17,0)) -> FALSE
A10: =IF(ISBLANK(E10),"","OFVP") -> OFVP | B10: Chicago Conveners | D10: 2773 | E10: UNIVERSAL FAMILY CONNECTION | G10: 45747 | H10: 24999.95 | I10: 2022 | J10: Chicago | K10: Cook | L10: Englewood | M10: =IF(ISNUMBER(MATCH(E10,_xlfn.VSTACK('VLookup Lists'!$E$2:$E$17,'VLookup Lists'!$H$2:$H$38,'VLookup Lists'!$J$2:$J$8),0)),1,0) -> 0 | N10: =IFERROR(IF(VLOOKUP($D10,'VLookup Lists'!$B$11:$C$29,2,FALSE)="FLIP",1,0),"") -> 0 | O10: =ISNUMBER(MATCH($E10,'VLookup Lists'!$E$2:$E$17,0)) -> FALSE
A11: =IF(ISBLANK(E11),"","OFVP") -> OFVP | B11: Chicago Conveners | D11: 2773 | E11: WHAT ABOUT US CHARITABLE | G11: 45747 | H11: 25000 | I11: 2022 | J11: Chicago | K11: Cook | L11: Austin | M11: =IF(ISNUMBER(MATCH(E11,_xlfn.VSTACK('VLookup Lists'!$E$2:$E$17,'VLookup Lists'!$H$2:$H$38,'VLookup Lists'!$J$2:$J$8),0)),1,0) -> 0 | N11: =IFERROR(IF(VLOOKUP($D11,'VLookup Lists'!$B$11:$C$29,2,FALSE)="FLIP",1,0),"") -> 0 | O11: =ISNUMBER(MATCH($E11,'VLookup Lists'!$E$2:$E$17,0)) -> FALSE
A12: =IF(ISBLANK(E12),"","OFVP") -> OFVP | B12: Chicago Conveners | D12: 2773 | E12: YMCA OF METROPOLITAN CHICAGO | G12: 45747 | H12: 24075 | I12: 2022 | J12: Chicago | K12: Cook | L12: Chicago Lawn | M12: =IF(ISNUMBER(MATCH(E12,_xlfn.VSTACK('VLookup Lists'!$E$2:$E$17,'VLookup Lists'!$H$2:$H$38,'VLookup Lists'!$J$2:$J$8),0)),1,0) -> 1 | N12: =IFERROR(IF(VLOOKUP($D12,'VLookup Lists'!$B$11:$C$29,2,FALSE)="FLIP",1,0),"") -> 0 | O12: =ISNUMBER(MATCH($E12,'VLookup Lists'!$E$2:$E$17,0)) -> FALSE
A13: =IF(ISBLANK(E13),"","OFVP") -> OFVP | B13: Chicago Conveners | D13: 2773 | E13: YMCA OF METROPOLITAN CHICAGO | G13: 45747 | H13: 24075 | I13: 2022 | J13: Chicago | K13: Cook | L13: East Garfield Park | M13: =IF(ISNUMBER(MATCH(E13,_xlfn.VSTACK('VLookup Lists'!$E$2:$E$17,'VLookup Lists'!$H$2:$H$38,'VLookup Lists'!$J$2:$J$8),0)),1,0) -> 1 | N13: =IFERROR(IF(VLOOKUP($D13,'VLookup Lists'!$B$11:$C$29,2,FALSE)="FLIP",1,0),"") -> 0 | O13: =ISNUMBER(MATCH($E13,'VLookup Lists'!$E$2:$E$17,0)) -> FALSE
... A42: =IF(ISBLANK(E42),"","OFVP") -> OFVP | B42: Violence Prevention | D42: 2774 | E42: The Restorative Project, Inc. | G42: 45688 | H42: 75000 | I42: 2022 | J42: Chicago | K42: Cook | L42: Chicago Lawn | M42: =IF(ISNUMBER(MATCH(E42,_xlfn.VSTACK('VLookup Lists'!$E$2:$E$17,'VLookup Lists'!$H$2:$H$38,'VLookup Lists'!$J$2:$J$8),0)),1,0) -> 1 | N42: =IFERROR(IF(VLOOKUP($D42,'VLookup Lists'!$B$11:$C$29,2,FALSE)="FLIP",1,0),"") -> 0 | O42: =ISNUMBER(MATCH($E42,'VLookup Lists'!$E$2:$E$17,0)) -> FALSE
A43: =IF(ISBLANK(E43),"","OFVP") -> OFVP | B43: Violence Prevention | D43: 2774 | E43: The Restorative Project, Inc. | H43: 75000 | I43: 2022 | J43: Chicago | K43: Cook | L43: Englewood | M43: =IF(ISNUMBER(MATCH(E43,_xlfn.VSTACK('VLookup Lists'!$E$2:$E$17,'VLookup Lists'!$H$2:$H$38,'VLookup Lists'!$J$2:$J$8),0)),1,0) -> 1 | N43: =IFERROR(IF(VLOOKUP($D43,'VLookup Lists'!$B$11:$C$29,2,FALSE)="FLIP",1,0),"") -> 0 | O43: =ISNUMBER(MATCH($E43,'VLookup Lists'!$E$2:$E$17,0)) -> FALSE
A44: =IF(ISBLANK(E44),"","OFVP") -> OFVP | B44: Violence Prevention | D44: 2774 | E44: The Restorative Project, Inc. | G44: 45688 | H44: 75000 | I44: 2022 | J44: Chicago | K44: Cook | L44: West Englewood | M44: =IF(ISNUMBER(MATCH(E44,_xlfn.VSTACK('VLookup Lists'!$E$2:$E$17,'VLookup Lists'!$H$2:$H$38,'VLookup Lists'!$J$2:$J$8),0)),1,0) -> 1 | N44: =IFERROR(IF(VLOOKUP($D44,'VLookup Lists'!$B$11:$C$29,2,FALSE)="FLIP",1,0),"") -> 0 | O44: =ISNUMBER(MATCH($E44,'VLookup Lists'!$E$2:$E$17,0)) -> FALSE
A45: =IF(ISBLANK(E45),"","OFVP") -> OFVP | B45: Violence Prevention | D45: 2774 | E45: Together Chicago, Inc. | G45: 45688 | H45: 74998 | I45: 2022 | J45: Chicago | K45: Cook | L45: Austin | M45: =IF(ISNUMBER(MATCH(E45,_xlfn.VSTACK('VLookup Lists'!$E$2:$E$17,'VLookup Lists'!$H$2:$H$38,'VLookup Lists'!$J$2:$J$8),0)),1,0) -> 1 | N45: =IFERROR(IF(VLOOKUP($D45,'VLookup Lists'!$B$11:$C$29,2,FALSE)="FLIP",1,0),"") -> 0 | O45: =ISNUMBER(MATCH($E45,'VLookup Lists'!$E$2:$E$17,0)) -> TRUE
A46: =IF(ISBLANK(E46),"","OFVP") -> OFVP | B46: Violence Prevention | D46: 2774 | E46: Together Chicago, Inc. | G46: 45688 | H46: 74998 | I46: 2022 | J46: Chicago | K46: Cook | L46: East Garfield Park | M46: =IF(ISNUMBER(MATCH(E46,_xlfn.VSTACK('VLookup Lists'!$E$2:$E$17,'VLookup Lists'!$H$2:$H$38,'VLookup Lists'!$J$2:$J$8),0)),1,0) -> 1 | N46: =IFERROR(IF(VLOOKUP($D46,'VLookup Lists'!$B$11:$C$29,2,FALSE)="FLIP",1,0),"") -> 0 | O46: =ISNUMBER(MATCH($E46,'VLookup Lists'!$E$2:$E$17,0)) -> TRUE
A47: =IF(ISBLANK(E47),"","OFVP") -> OFVP | B47: Violence Prevention | D47: 2774 | E47: UCAN | G47: 45688 | H47: 99223 | I47: 2022 | J47: Chicago | K47: Cook | L47: North Lawndale | M47: =IF(ISNUMBER(MATCH(E47,_xlfn.VSTACK('VLookup Lists'!$E$2:$E$17,'VLookup Lists'!$H$2:$H$38,'VLookup Lists'!$J$2:$J$8),0)),1,0) -> 1 | N47: =IFERROR(IF(VLOOKUP($D47,'VLookup Lists'!$B$11:$C$29,2,FALSE)="FLIP",1,0),"") -> 0 | O47: =ISNUMBER(MATCH($E47,'VLookup Lists'!$E$2:$E$17,0)) -> TRUE
A48: =IF(ISBLANK(E48),"","OFVP") -> OFVP | B48: Violence Prevention | D48: 2774 | E48: The University of Chicago Medical Center | G48: 45688 | H48: 43123 | I48: 2022 | J48: Chicago | K48: Cook | L48: South Chicago | M48: =IF(ISNUMBER(MATCH(E48,_xlfn.VSTACK('VLookup Lists'!$E$2:$E$17,'VLookup Lists'!$H$2:$H$38,'VLookup Lists'!$J$2:$J$8),0)),1,0) -> 0 | N48: =IFERROR(IF(VLOOKUP($D48,'VLookup Lists'!$B$11:$C$29,2,FALSE)="FLIP",1,0),"") -> 0 | O48: =ISNUMBER(MATCH($E48,'VLookup Lists'!$E$2:$E$17,0)) -> FALSE
A49: =IF(ISBLANK(E49),"","OFVP") -> OFVP | B49: Violence Prevention | D49: 2774 | E49: The University of Chicago Medical Center | G49: 45838 | H49: 43123 | I49: 2022 | J49: Chicago | K49: Cook | L49: South Shore | M49: =IF(ISNUMBER(MATCH(E49,_xlfn.VSTACK('VLookup Lists'!$E$2:$E$17,'VLookup Lists'!$H$2:$H$38,'VLookup Lists'!$J$2:$J$8),0)),1,0) -> 0 | N49: =IFERROR(IF(VLOOKUP($D49,'VLookup Lists'!$B$11:$C$29,2,FALSE)="FLIP",1,0),"") -> 0 | O49: =ISNUMBER(MATCH($E49,'VLookup Lists'!$E$2:$E$17,0)) -> FALSE
A50: =IF(ISBLANK(E50),"","OFVP") -> OFVP | B50: Violence Prevention | D50: 2774 | E50: The University of Chicago Medical Center | G50: 45688 | H50: 43123 | I50: 2022 | J50: Chicago | K50: Cook | L50: Woodlawn | M50: =IF(ISNUMBER(MATCH(E50,_xlfn.VSTACK('VLookup Lists'!$E$2:$E$17,'VLookup Lists'!$H$2:$H$38,'VLookup Lists'!$J$2:$J$8),0)),1,0) -> 0 | N50: =IFERROR(IF(VLOOKUP($D50,'VLookup Lists'!$B$11:$C$29,2,FALSE)="FLIP",1,0),"") -> 0 | O50: =ISNUMBER(MATCH($E50,'VLookup Lists'!$E$2:$E$17,0)) -> FALSE
A51: =IF(ISBLANK(E51),"","OFVP") -> OFVP | B51: Violence Prevention | D51: 2774 | E51: YMCA OF METROPOLITAN CHICAGO | G51: 45688 | H51: 74860 | I51: 2022 | J51: Chicago | K51: Cook | L51: Humboldt Park | M51: =IF(ISNUMBER(MATCH(E51,_xlfn.VSTACK('VLookup Lists'!$E$2:$E$17,'VLookup Lists'!$H$2:$H$38,'VLookup Lists'!$J$2:$J$8),0)),1,0) -> 1 | N51: =IFERROR(IF(VLOOKUP($D51,'VLookup Lists'!$B$11:$C$29,2,FALSE)="FLIP",1,0),"") -> 0 | O51: =ISNUMBER(MATCH($E51,'VLookup Lists'!$E$2:$E$17,0)) -> FALSE
A52: =IF(ISBLANK(E52),"","OFVP") -> OFVP | B52: Violence Prevention | D52: 2774 | E52: YMCA OF METROPOLITAN CHICAGO | G52: 45688 | H52: 73647 | I52: 2022 | J52: Chicago | K52: Cook | L52: South Lawndale | M52: =IF(ISNUMBER(MATCH(E52,_xlfn.VSTACK('VLookup Lists'!$E$2:$E$17,'VLookup Lists'!$H$2:$H$38,'VLookup Lists'!$J$2:$J$8),0)),1,0) -> 1 | N52: =IFERROR(IF(VLOOKUP($D52,'VLookup Lists'!$B$11:$C$29,2,FALSE)="FLIP",1,0),"") -> 0 | O52: =ISNUMBER(MATCH($E52,'VLookup Lists'!$E$2:$E$17,0)) -> FALSE
A53: =IF(ISBLANK(E53),"","OFVP") -> OFVP | B53: Violence Prevention | D53: 2774 | E53: YMCA OF METROPOLITAN CHICAGO | G53: 45688 | H53: 73647 | I53: 2022 | J53: Chicago | K53: Cook | L53: Woodlawn | M53: =IF(ISNUMBER(MATCH(E53,_xlfn.VSTACK('VLookup Lists'!$E$2:$E$17,'VLookup Lists'!$H$2:$H$38,'VLookup Lists'!$J$2:$J$8),0)),1,0) -> 1 | N53: =IFERROR(IF(VLOOKUP($D53,'VLookup Lists'!$B$11:$C$29,2,FALSE)="FLIP",1,0),"") -> 0 | O53: =ISNUMBER(MATCH($E53,'VLookup Lists'!$E$2:$E$17,0)) -> FALSE
A54: =IF(ISBLANK(E54),"","OFVP") -> OFVP | B54: Youth Development | D54: 2775 | E54: Artists ReEnvisioning Tomorrow Inc. | G54: 45473 | H54: 24110 | I54: 2022 | J54: Greater Illinois | K54: Peoria | L54: Peoria | M54: =IF(ISNUMBER(MATCH(E54,_xlfn.VSTACK('VLookup Lists'!$E$2:$E$17,'VLookup Lists'!$H$2:$H$38,'VLookup Lists'!$J$2:$J$8),0)),1,0) -> 0 | N54: =IFERROR(IF(VLOOKUP($D54,'VLookup Lists'!$B$11:$C$29,2,FALSE)="FLIP",1,0),"") -> 0 | O54: =ISNUMBER(MATCH($E54,'VLookup Lists'!$E$2:$E$17,0)) -> FALSE
A55: =IF(ISBLANK(E55),"","OFVP") -> OFVP | B55: Youth Development | D55: 2775 | E55: AURORA AREA AFRICAN AMERICAN MEN OF UNITY | G55: 45473 | H55: 25466 | I55: 2022 | J55: Greater Illinois | K55: Dupage, Kane, Kendall, Will | L55: Aurora | M55: =IF(ISNUMBER(MATCH(E55,_xlfn.VSTACK('VLookup Lists'!$E$2:$E$17,'VLookup Lists'!$H$2:$H$38,'VLookup Lists'!$J$2:$J$8),0)),1,0) -> 0 | N55: =IFERROR(IF(VLOOKUP($D55,'VLookup Lists'!$B$11:$C$29,2,FALSE)="FLIP",1,0),"") -> 0 | O55: =ISNUMBER(MATCH($E55,'VLookup Lists'!$E$2:$E$17,0)) -> FALSE
... A75: =IF(ISBLANK(E75),"","OFVP") -> OFVP | B75: Youth Development | D75: 2775 | E75: YMCA OF ROCK RIVER VALLEY | G75: 45473 | H75: 12396 | I75: 2022 | J75: Greater Illinois | K75: Winnebago | L75: Rockford | M75: =IF(ISNUMBER(MATCH(E75,_xlfn.VSTACK('VLookup Lists'!$E$2:$E$17,'VLookup Lists'!$H$2:$H$38,'VLookup Lists'!$J$2:$J$8),0)),1,0) -> 0 | N75: =IFERROR(IF(VLOOKUP($D75,'VLookup Lists'!$B$11:$C$29,2,FALSE)="FLIP",1,0),"") -> 0 | O75: =ISNUMBER(MATCH($E75,'VLookup Lists'!$E$2:$E$17,0)) -> FALSE
A76: =IF(ISBLANK(E76),"","OFVP") -> OFVP | B76: High Risk Youth Intervention Services | D76: 2776 | E76: Brightpoint (formerly Children's Home and Aid Society of Illinois) | H76: 74870 | I76: 2022 | J76: Chicago | K76: Cook | L76: z HRYIS | M76: =IF(ISNUMBER(MATCH(E76,_xlfn.VSTACK('VLookup Lists'!$E$2:$E$17,'VLookup Lists'!$H$2:$H$38,'VLookup Lists'!$J$2:$J$8),0)),1,0) -> 0 | N76: =IFERROR(IF(VLOOKUP($D76,'VLookup Lists'!$B$11:$C$29,2,FALSE)="FLIP",1,0),"") -> 0 | O76: =ISNUMBER(MATCH($E76,'VLookup Lists'!$E$2:$E$17,0)) -> FALSE
A77: =IF(ISBLANK(E77),"","OFVP") -> OFVP | B77: High Risk Youth Intervention Services | D77: 2776 | E77: Community Counseling Center (C4) | H77: 124409 | I77: 2022 | J77: Chicago | K77: Cook | L77: z HRYIS | M77: =IF(ISNUMBER(MATCH(E77,_xlfn.VSTACK('VLookup Lists'!$E$2:$E$17,'VLookup Lists'!$H$2:$H$38,'VLookup Lists'!$J$2:$J$8),0)),1,0) -> 0 | N77: =IFERROR(IF(VLOOKUP($D77,'VLookup Lists'!$B$11:$C$29,2,FALSE)="FLIP",1,0),"") -> 0 | O77: =ISNUMBER(MATCH($E77,'VLookup Lists'!$E$2:$E$17,0)) -> FALSE
A78: =IF(ISBLANK(E78),"","OFVP") -> OFVP | B78: High Risk Youth Intervention Services | D78: 2776 | E78: Metropolitan Family Services | H78: 100499 | I78: 2022 | J78: Chicago | K78: Cook | L78: z HRYIS | M78: =IF(ISNUMBER(MATCH(E78,_xlfn.VSTACK('VLookup Lists'!$E$2:$E$17,'VLookup Lists'!$H$2:$H$38,'VLookup Lists'!$J$2:$J$8),0)),1,0) -> 1 | N78: =IFERROR(IF(VLOOKUP($D78,'VLookup Lists'!$B$11:$C$29,2,FALSE)="FLIP",1,0),"") -> 0 | O78: =ISNUMBER(MATCH($E78,'VLookup Lists'!$E$2:$E$17,0)) -> TRUE
A79: =IF(ISBLANK(E79),"","OFVP") -> OFVP | B79: High Risk Youth Intervention Services | D79: 2776 | E79: MOUNT SINAI HOSP MEDICAL | G79: 45838 | H79: 49410 | I79: 2022 | J79: Chicago | K79: Cook | L79: z HRYIS | M79: =IF(ISNUMBER(MATCH(E79,_xlfn.VSTACK('VLookup Lists'!$E$2:$E$17,'VLookup Lists'!$H$2:$H$38,'VLookup Lists'!$J$2:$J$8),0)),1,0) -> 0 | N79: =IFERROR(IF(VLOOKUP($D79,'VLookup Lists'!$B$11:$C$29,2,FALSE)="FLIP",1,0),"") -> 0 | O79: =ISNUMBER(MATCH($E79,'VLookup Lists'!$E$2:$E$17,0)) -> FALSE
A80: =IF(ISBLANK(E80),"","OFVP") -> OFVP | B80: Trauma-Informed Behavioral Health | D80: 2600 | E80: Alternatives, Inc. | H80: 228823 | I80: 2023 | J80: Greater Illinois | K80: Lake | L80: Waukegan-North Chicago Cluster | M80: =IF(ISNUMBER(MATCH(E80,_xlfn.VSTACK('VLookup Lists'!$E$2:$E$17,'VLookup Lists'!$H$2:$H$38,'VLookup Lists'!$J$2:$J$8),0)),1,0) -> 0 | N80: =IFERROR(IF(VLOOKUP($D80,'VLookup Lists'!$B$11:$C$29,2,FALSE)="FLIP",1,0),"") -> 0 | O80: =ISNUMBER(MATCH($E80,'VLookup Lists'!$E$2:$E$17,0)) -> FALSE
A81: =IF(ISBLANK(E81),"","OFVP") -> OFVP | B81: Trauma-Informed Behavioral Health | D81: 2600 | E81: Brightpoint (formerly Children's Home and Aid Society of Illinois) | G81: 45838 | H81: 155307 | I81: 2023 | J81: Greater Illinois | K81: St. Clair | L81: Belleville Cluster | M81: =IF(ISNUMBER(MATCH(E81,_xlfn.VSTACK('VLookup Lists'!$E$2:$E$17,'VLookup Lists'!$H$2:$H$38,'VLookup Lists'!$J$2:$J$8),0)),1,0) -> 0 | N81: =IFERROR(IF(VLOOKUP($D81,'VLookup Lists'!$B$11:$C$29,2,FALSE)="FLIP",1,0),"") -> 0 | O81: =ISNUMBER(MATCH($E81,'VLookup Lists'!$E$2:$E$17,0)) -> FALSE
A82: =IF(ISBLANK(E82),"","OFVP") -> OFVP | B82: Trauma-Informed Behavioral Health | D82: 2600 | E82: Comprehensive Community Solutions, Inc. | H82: 318806 | I82: 2023 | J82: Greater Illinois | K82: Winnebago | L82: Rockford | M82: =IF(ISNUMBER(MATCH(E82,_xlfn.VSTACK('VLookup Lists'!$E$2:$E$17,'VLookup Lists'!$H$2:$H$38,'VLookup Lists'!$J$2:$J$8),0)),1,0) -> 0 | N82: =IFERROR(IF(VLOOKUP($D82,'VLookup Lists'!$B$11:$C$29,2,FALSE)="FLIP",1,0),"") -> 0 | O82: =ISNUMBER(MATCH($E82,'VLookup Lists'!$E$2:$E$17,0)) -> FALSE
A83: =IF(ISBLANK(E83),"","OFVP") -> OFVP | B83: Trauma-Informed Behavioral Health | D83: 2600 | E83: FAMILY SERVICE AND MENTAL HEALTH CENTER OF CICERO | H83: 175000 | I83: 2023 | J83: Greater Illinois | K83: Cook | L83: Berwyn-Cicero Cluster | M83: =IF(ISNUMBER(MATCH(E83,_xlfn.VSTACK('VLookup Lists'!$E$2:$E$17,'VLookup Lists'!$H$2:$H$38,'VLookup Lists'!$J$2:$J$8),0)),1,0) -> 0 | N83: =IFERROR(IF(VLOOKUP($D83,'VLookup Lists'!$B$11:$C$29,2,FALSE)="FLIP",1,0),"") -> 0 | O83: =ISNUMBER(MATCH($E83,'VLookup Lists'!$E$2:$E$17,0)) -> FALSE
A84: =IF(ISBLANK(E84),"","OFVP") -> OFVP | B84: Trauma-Informed Behavioral Health | D84: 2600 | E84: GOODWILL INDUSTRIES OF CENTRAL ILLINOIS | H84: 128028 | I84: 2023 | J84: Greater Illinois | K84: Peoria | L84: Peoria | M84: =IF(ISNUMBER(MATCH(E84,_xlfn.VSTACK('VLookup Lists'!$E$2:$E$17,'VLookup Lists'!$H$2:$H$38,'VLookup Lists'!$J$2:$J$8),0)),1,0) -> 0 | N84: =IFERROR(IF(VLOOKUP($D84,'VLookup Lists'!$B$11:$C$29,2,FALSE)="FLIP",1,0),"") -> 0 | O84: =ISNUMBER(MATCH($E84,'VLookup Lists'!$E$2:$E$17,0)) -> FALSE
A85: =IF(ISBLANK(E85),"","OFVP") -> OFVP | B85: Trauma-Informed Behavioral Health | D85: 2600 | E85: KIDS ABOVE ALL | H85: 177001 | I85: 2023 | J85: Greater Illinois | K85: Lake | L85: Waukegan-North Chicago Cluster | M85: =IF(ISNUMBER(MATCH(E85,_xlfn.VSTACK('VLookup Lists'!$E$2:$E$17,'VLookup Lists'!$H$2:$H$38,'VLookup Lists'!$J$2:$J$8),0)),1,0) -> 0 | N85: =IFERROR(IF(VLOOKUP($D85,'VLookup Lists'!$B$11:$C$29,2,FALSE)="FLIP",1,0),"") -> 0 | O85: =ISNUMBER(MATCH($E85,'VLookup Lists'!$E$2:$E$17,0)) -> FALSE
A86: =IF(ISBLANK(E86),"","OFVP") -> OFVP | B86: Trauma-Informed Behavioral Health | D86: 2600 | E86: Lake County Crisis Center for the Prevention and Treatment of Domestic Violence, INC DBA A Safe Place | H86: 175000 | I86: 2023 | J86: Greater Illinois | K86: Lake | L86: Waukegan-North Chicago Cluster | M86: =IF(ISNUMBER(MATCH(E86,_xlfn.VSTACK('VLookup Lists'!$E$2:$E$17,'VLookup Lists'!$H$2:$H$38,'VLookup Lists'!$J$2:$J$8),0)),1,0) -> 0 | N86: =IFERROR(IF(VLOOKUP($D86,'VLookup Lists'!$B$11:$C$29,2,FALSE)="FLIP",1,0),"") -> 0 | O86: =ISNUMBER(MATCH($E86,'VLookup Lists'!$E$2:$E$17,0)) -> FALSE
A87: =IF(ISBLANK(E87),"","OFVP") -> OFVP | B87: Trauma-Informed Behavioral Health | D87: 2600 | E87: Pilsen Wellness Center, Inc. | H87: 175000 | I87: 2023 | J87: Greater Illinois | K87: Cook | L87: Berwyn-Cicero Cluster | M87: =IF(ISNUMBER(MATCH(E87,_xlfn.VSTACK('VLookup Lists'!$E$2:$E$17,'VLookup Lists'!$H$2:$H$38,'VLookup Lists'!$J$2:$J$8),0)),1,0) -> 0 | N87: =IFERROR(IF(VLOOKUP($D87,'VLookup Lists'!$B$11:$C$29,2,FALSE)="FLIP",1,0),"") -> 0 | O87: =ISNUMBER(MATCH($E87,'VLookup Lists'!$E$2:$E$17,0)) -> FALSE
...

Sheet IJCIA Pivot
B2: Source | C2: (All)
B4: Sum of Award Amount | C4: Column Labels
B5: Row Labels | C5: 2019 | D5: 2020 | E5: 2021 | F5: 2022 | G5: 2023 | H5: 2024 | I5: 2025 | J5: 2026 | K5: (blank) | L5: Grand Total
B7: 100 ways foundation | H7: 200000 | L7: 200000
B8: 1863FWD LLC | E8: 629347 | F8: 629347 | G8: 629347 | H8: 629347 | L8: 2517388
B9: A & L YOUTH AND FAMILY SERVICES | I9: 455590 | J9: 1366770 | L9: 1822360
B10: A Gift of Love Charity, Inc. | I10: 118047 | J10: 118047 | L10: 236094
B11: A Just Harvest | G11: 1731000 | H11: 1731000 | I11: 1731000 | L11: 5193000
B12: A Knock At Midnight, NFP | G12: 1950000 | H12: 1950000 | I12: 1950000 | J12: 175000 | L12: 6025000
B13: A Safe Haven Foundation | D13: 500000 | E13: 500000 | F13: 750000 | G13: 2728171 | H13: 1978171 | I13: 1978171 | L13: 8434513
B14: Academic Development Institute, Inc. | E14: 2788584 | F14: 2788584 | G14: 2788584 | H14: 2788584 | I14: 249960 | J14: 949877 | L14: 12354173
B15: Acclivus, Inc. | E15: 6546400 | F15: 7378370 | G15: 7087000 | H15: 7500000 | I15: 4759600 | J15: 7500000 | L15: 40771370
B16: Adler University | F16: 70399 | G16: 70399 | H16: 191000 | I16: 753700 | J16: 562700 | L16: 1648198
B17: ADV & SAS | G17: 92831 | H17: 92831 | I17: 92831 | L17: 278493
B18: Advocacy Network for Children | D18: 175975 | E18: 175975 | H18: 90584 | I18: 181168 | J18: 181168 | L18: 804870
B19: Advocate Condell Medical Center | F19: 781793 | G19: 1563586 | H19: 1531793 | I19: 1500000 | J19: 1500000 | L19: 6877172
B20: Advocate Health and Hospitals Corporation | F20: 1200000 | G20: 2400000 | H20: 2700000 | I20: 2250000 | J20: 1500000 | L20: 10050000
B21: Alliance Against Intoxicated Motorists | E21: 375750 | F21: 939375 | G21: 563625 | H21: 563625 | L21: 2442375
B22: Alliance of Local Service Organizations (ALSO) | E22: 324965 | F22: 812453 | G22: 664788 | H22: 1184488 | I22: 1197000 | J22: 697000 | L22: 4880694
B23: ALPHA AND OMEGA FOUNDATION | G23: 255000 | H23: 255000 | I23: 483700 | J23: 686100 | L23: 1679800
B24: Alternatives, Inc. | D24: 317210 | E24: 1859201 | F24: 1708272 | G24: 1541991 | H24: 1541991 | I24: 399074 | L24: 7367739
B25: AMO Athletics Foundation | J25: 200000 | L25: 200000
B26: Angel of God Resource Center, Inc. | I26: 925500 | J26: 625500 | L26: 1551000
B27: Angels Boxing Academy, Limited | G27: 270000 | H27: 300000 | I27: 300000 | J27: 300000 | L27: 1170000
B28: Ann & Robert H. Lurie Children's Hospital of Chicago | C28: 805814 | D28: 805814 | E28: 805814 | F28: 937385 | L28: 3354827
B29: Annie B. Jones Civic Arts Center. | H29: 253022 | L29: 253022
B30: Apna Ghar, Inc. | H30: 97858 | L30: 97858
B31: Area Consortium of Educational Services (ACES) 4 Our Youth | F31: 225436 | L31: 225436
B32: Arrowleaf (formerly Family Counseling Center, Inc.) | E32: 932524 | F32: 932524 | G32: 932524 | H32: 932524 | I32: 121624 | L32: 3851720
B33: Artists ReEnvisioning Tomorrow Inc. | G33: 1800000 | H33: 1800000 | I33: 1800000 | L33: 5400000
B34: Ascend Justice | E34: 478400 | F34: 837200 | G34: 837200 | H34: 478400 | I34: 500000 | J34: 478400 | L34: 3609600
B35: Ascending Knowledge Community Outreach International | I35: 477172 | J35: 477172 | L35: 954344
B36: Association for Individual Development | G36: 1472460 | H36: 1472460 | I36: 1472460 | L36: 4417380
B37: Aurora Area Interfaith Food Pantry | G37: 750000 | H37: 750000 | I37: 750000 | L37: 2250000
B38: BandWith Chicago | F38: 60465 | I38: 145116 | J38: 149604 | L38: 355185
B39: BEDS Plus Care, Inc. | D39: 327156 | E39: 327156 | F39: 446160 | G39: 446160 | L39: 1546632
B40: Bella Ease | G40: 600000 | H40: 829844 | I40: 600000 | J40: 200000 | L40: 2229844
B41: Bethel Family Resource Center | F41: 164860 | L41: 164860
B42: Between Friends | F42: 109399 | I42: 262558 | J42: 200000 | L42: 571957
B43: Beyond the Ball NFP | G43: 147000 | H43: 147000 | I43: 147000 | L43: 441000
...

Sheet ICJIA
A1: Source | B1: Grant Type | C1: Award ID | D1: CSFA | E1: Grantee Name | F1: Start Date | G1: End Date | H1: Award Amount | I1: Fiscal Year | J1: Chicago/Greater Illinois | K1: County | L1: Community Area | M1: CVI | N1: FLIP | O1: CP4P | P1: SC2o | Q1: SC2c
A2: =IF(ISBLANK(B2),"","ICJIA") -> ICJIA | B2: Community-based Violence Intervention & Prevention (Fed) | C2: 662314 JES | D2: 3380 | E2: Angel of God Resource Center, Inc. | F2: 45566 | G2: 45930 | H2: 300000 | I2: 2025 | M2: =IF(ISNUMBER(MATCH(E2,_xlfn.VSTACK('VLookup Lists'!$E$2:$E$17,'VLookup Lists'!$H$2:$H$38,'VLookup Lists'!$J$2:$J$8),0)),1,0) -> 0 | N2: =IFERROR(IF(VLOOKUP($D2,'VLookup Lists'!$B$11:$C$29,2,FALSE)="FLIP",1,0),"") | O2: =ISNUMBER(MATCH($E2,'VLookup Lists'!$E$2:$E$17,0)) -> FALSE
A3: =IF(ISBLANK(B3),"","ICJIA") -> ICJIA | B3: Community-based Violence Intervention & Prevention (Fed) | C3: 662315 JES | D3: 3380 | E3: Breakthrough Urban Ministries | F3: 45566 | G3: 45930 | H3: 128577 | I3: 2025 | M3: =IF(ISNUMBER(MATCH(E3,_xlfn.VSTACK('VLookup Lists'!$E$2:$E$17,'VLookup Lists'!$H$2:$H$38,'VLookup Lists'!$J$2:$J$8),0)),1,0) -> 1 | N3: =IFERROR(IF(VLOOKUP($D3,'VLookup Lists'!$B$11:$C$29,2,FALSE)="FLIP",1,0),"") | O3: =ISNUMBER(MATCH($E3,'VLookup Lists'!$E$2:$E$17,0)) -> TRUE
A4: =IF(ISBLANK(B4),"","ICJIA") -> ICJIA | B4: Community-based Violence Intervention & Prevention (Fed) | C4: 662313 JES | D4: 3380 | E4: BUILD Inc. | F4: 45566 | G4: 45930 | H4: 260640 | I4: 2025 | M4: =IF(ISNUMBER(MATCH(E4,_xlfn.VSTACK('VLookup Lists'!$E$2:$E$17,'VLookup Lists'!$H$2:$H$38,'VLookup Lists'!$J$2:$J$8),0)),1,0) -> 1 | N4: =IFERROR(IF(VLOOKUP($D4,'VLookup Lists'!$B$11:$C$29,2,FALSE)="FLIP",1,0),"") | O4: =ISNUMBER(MATCH($E4,'VLookup Lists'!$E$2:$E$17,0)) -> FALSE
A5: =IF(ISBLANK(B5),"","ICJIA") -> ICJIA | B5: Community-based Violence Intervention & Prevention (Fed) | C5: 662310 JES | D5: 3380 | E5: Lawndale Christian Legal Center | F5: 45474 | G5: 45838 | H5: 100000 | I5: 2025 | M5: =IF(ISNUMBER(MATCH(E5,_xlfn.VSTACK('VLookup Lists'!$E$2:$E$17,'VLookup Lists'!$H$2:$H$38,'VLookup Lists'!$J$2:$J$8),0)),1,0) -> 0 | N5: =IFERROR(IF(VLOOKUP($D5,'VLookup Lists'!$B$11:$C$29,2,FALSE)="FLIP",1,0),"") | O5: =ISNUMBER(MATCH($E5,'VLookup Lists'!$E$2:$E$17,0)) -> FALSE
A6: =IF(ISBLANK(B6),"","ICJIA") -> ICJIA | B6: Community-based Violence Intervention & Prevention (Fed) | C6: 662311 JES | D6: 3380 | E6: New Eclipse Community Alliance | F6: 45566 | G6: 45930 | H6: 614014 | I6: 2025 | M6: =IF(ISNUMBER(MATCH(E6,_xlfn.VSTACK('VLookup Lists'!$E$2:$E$17,'VLookup Lists'!$H$2:$H$38,'VLookup Lists'!$J$2:$J$8),0)),1,0) -> 0 | N6: =IFERROR(IF(VLOOKUP($D6,'VLookup Lists'!$B$11:$C$29,2,FALSE)="FLIP",1,0),"") | O6: =ISNUMBER(MATCH($E6,'VLookup Lists'!$E$2:$E$17,0)) -> FALSE
A7: =IF(ISBLANK(B7),"","ICJIA") -> ICJIA | B7: Community-based Violence Intervention & Prevention (Fed) | C7: 662312 JS | D7: 3380 | E7: Roseland Ceasefire Project Inc. | F7: 45474 | G7: 45838 | H7: 177455 | I7: 2025 | M7: =IF(ISNUMBER(MATCH(E7,_xlfn.VSTACK('VLookup Lists'!$E$2:$E$17,'VLookup Lists'!$H$2:$H$38,'VLookup Lists'!$J$2:$J$8),0)),1,0) -> 1 | N7: =IFERROR(IF(VLOOKUP($D7,'VLookup Lists'!$B$11:$C$29,2,FALSE)="FLIP",1,0),"") | O7: =ISNUMBER(MATCH($E7,'VLookup Lists'!$E$2:$E$17,0)) -> FALSE
A8: =IF(ISBLANK(B8),"","ICJIA") -> ICJIA | B8: Community-based Violence Intervention & Prevention (Fed) | C8: 662316 JES | D8: 3380 | E8: Southwest Organizing Project (SWOP) | F8: 45566 | G8: 45930 | H8: 214461 | I8: 2025 | M8: =IF(ISNUMBER(MATCH(E8,_xlfn.VSTACK('VLookup Lists'!$E$2:$E$17,'VLookup Lists'!$H$2:$H$38,'VLookup Lists'!$J$2:$J$8),0)),1,0) -> 1 | N8: =IFERROR(IF(VLOOKUP($D8,'VLookup Lists'!$B$11:$C$29,2,FALSE)="FLIP",1,0),"") | O8: =ISNUMBER(MATCH($E8,'VLookup Lists'!$E$2:$E$17,0)) -> TRUE
A9: =IF(ISBLANK(B9),"","ICJIA") -> ICJIA | B9: Community-Based Violence Intervention and Prevention (CB-VIP) | C9: 172000 SW | D9: 2117 | E9: Alternatives, Inc. | F9: 43647 | G9: 44012 | H9: 317210 | I9: 2020 | M9: =IF(ISNUMBER(MATCH(E9,_xlfn.VSTACK('VLookup Lists'!$E$2:$E$17,'VLookup Lists'!$H$2:$H$38,'VLookup Lists'!$J$2:$J$8),0)),1,0) -> 0 | N9: =IFERROR(IF(VLOOKUP($D9,'VLookup Lists'!$B$11:$C$29,2,FALSE)="FLIP",1,0),"") | O9: =ISNUMBER(MATCH($E9,'VLookup Lists'!$E$2:$E$17,0)) -> FALSE
A10: =IF(ISBLANK(B10),"","ICJIA") -> ICJIA | B10: Community-Based Violence Intervention and Prevention (CB-VIP) | C10: 172001 | D10: 2117 | E10: BIG BROTHERS-BIG SISTERS OF METROPOLITAN CHICAGO | F10: 43647 | G10: 44012 | H10: 291588 | I10: 2020 | M10: =IF(ISNUMBER(MATCH(E10,_xlfn.VSTACK('VLookup Lists'!$E$2:$E$17,'VLookup Lists'!$H$2:$H$38,'VLookup Lists'!$J$2:$J$8),0)),1,0) -> 0 | N10: =IFERROR(IF(VLOOKUP($D10,'VLookup Lists'!$B$11:$C$29,2,FALSE)="FLIP",1,0),"") | O10: =ISNUMBER(MATCH($E10,'VLookup Lists'!$E$2:$E$17,0)) -> FALSE
A11: =IF(ISBLANK(B11),"","ICJIA") -> ICJIA | B11: Community-Based Violence Intervention and Prevention (CB-VIP) | C11: 172002 STB | D11: 2117 | E11: Bright Star Community Outreach | F11: 43647 | G11: 44012 | H11: 690921 | I11: 2020 | M11: =IF(ISNUMBER(MATCH(E11,_xlfn.VSTACK('VLookup Lists'!$E$2:$E$17,'VLookup Lists'!$H$2:$H$38,'VLookup Lists'!$J$2:$J$8),0)),1,0) -> 0 | N11: =IFERROR(IF(VLOOKUP($D11,'VLookup Lists'!$B$11:$C$29,2,FALSE)="FLIP",1,0),"") | O11: =ISNUMBER(MATCH($E11,'VLookup Lists'!$E$2:$E$17,0)) -> FALSE
A12: =IF(ISBLANK(B12),"","ICJIA") -> ICJIA | B12: Community-Based Violence Intervention and Prevention (CB-VIP) | C12: 172003 STB | D12: 2117 | E12: Cabrini Green Legal AId | F12: 43647 | G12: 44012 | H12: 173418 | I12: 2020 | M12: =IF(ISNUMBER(MATCH(E12,_xlfn.VSTACK('VLookup Lists'!$E$2:$E$17,'VLookup Lists'!$H$2:$H$38,'VLookup Lists'!$J$2:$J$8),0)),1,0) -> 0 | N12: =IFERROR(IF(VLOOKUP($D12,'VLookup Lists'!$B$11:$C$29,2,FALSE)="FLIP",1,0),"") | O12: =ISNUMBER(MATCH($E12,'VLookup Lists'!$E$2:$E$17,0)) -> FALSE
A13: =IF(ISBLANK(B13),"","ICJIA") -> ICJIA | B13: Community-Based Violence Intervention and Prevention (CB-VIP) | C13: 172004 | D13: 2117 | E13: Catholic Charities of the Archdiocese of Chicago | F13: 43647 | G13: 44012 | H13: 569782 | I13: 2020 | M13: =IF(ISNUMBER(MATCH(E13,_xlfn.VSTACK('VLookup Lists'!$E$2:$E$17,'VLookup Lists'!$H$2:$H$38,'VLookup Lists'!$J$2:$J$8),0)),1,0) -> 0 | N13: =IFERROR(IF(VLOOKUP($D13,'VLookup Lists'!$B$11:$C$29,2,FALSE)="FLIP",1,0),"") | O13: =ISNUMBER(MATCH($E13,'VLookup Lists'!$E$2:$E$17,0)) -> FALSE
A14: =IF(ISBLANK(B14),"","ICJIA") -> ICJIA | B14: Community-Based Violence Intervention and Prevention (CB-VIP) | C14: 172005 | D14: 2117 | E14: Children's Home & Aid Society of Illinois dba Brightpoint | F14: 43647 | G14: 44012 | H14: 102173 | I14: 2020 | M14: =IF(ISNUMBER(MATCH(E14,_xlfn.VSTACK('VLookup Lists'!$E$2:$E$17,'VLookup Lists'!$H$2:$H$38,'VLookup Lists'!$J$2:$J$8),0)),1,0) -> 0 | N14: =IFERROR(IF(VLOOKUP($D14,'VLookup Lists'!$B$11:$C$29,2,FALSE)="FLIP",1,0),"") | O14: =ISNUMBER(MATCH($E14,'VLookup Lists'!$E$2:$E$17,0)) -> FALSE
A15: =IF(ISBLANK(B15),"","ICJIA") -> ICJIA | B15: Community-Based Violence Intervention and Prevention (CB-VIP) | C15: 172006 STB | D15: 2117 | E15: Gary Comer Youth Center, Inc. | F15: 43647 | G15: 44012 | H15: 807505 | I15: 2020 | M15: =IF(ISNUMBER(MATCH(E15,_xlfn.VSTACK('VLookup Lists'!$E$2:$E$17,'VLookup Lists'!$H$2:$H$38,'VLookup Lists'!$J$2:$J$8),0)),1,0) -> 0 | N15: =IFERROR(IF(VLOOKUP($D15,'VLookup Lists'!$B$11:$C$29,2,FALSE)="FLIP",1,0),"") | O15: =ISNUMBER(MATCH($E15,'VLookup Lists'!$E$2:$E$17,0)) -> FALSE
A16: =IF(ISBLANK(B16),"","ICJIA") -> ICJIA | B16: Community-Based Violence Intervention and Prevention (CB-VIP) | C16: 172007 STB | D16: 2117 | E16: Heartland Alliance | F16: 43647 | G16: 44012 | H16: 659942 | I16: 2020 | M16: =IF(ISNUMBER(MATCH(E16,_xlfn.VSTACK('VLookup Lists'!$E$2:$E$17,'VLookup Lists'!$H$2:$H$38,'VLookup Lists'!$J$2:$J$8),0)),1,0) -> 0 | N16: =IFERROR(IF(VLOOKUP($D16,'VLookup Lists'!$B$11:$C$29,2,FALSE)="FLIP",1,0),"") | O16: =ISNUMBER(MATCH($E16,'VLookup Lists'!$E$2:$E$17,0)) -> FALSE
A17: =IF(ISBLANK(B17),"","ICJIA") -> ICJIA | B17: Community-Based Violence Intervention and Prevention (CB-VIP) | C17: 172008 SW | D17: 2117 | E17: Illinois Association of Juvenile Justice Councils | F17: 43647 | G17: 44012 | H17: 929606 | I17: 2020 | M17: =IF(ISNUMBER(MATCH(E17,_xlfn.VSTACK('VLookup Lists'!$E$2:$E$17,'VLookup Lists'!$H$2:$H$38,'VLookup Lists'!$J$2:$J$8),0)),1,0) -> 0 | N17: =IFERROR(IF(VLOOKUP($D17,'VLookup Lists'!$B$11:$C$29,2,FALSE)="FLIP",1,0),"") | O17: =ISNUMBER(MATCH($E17,'VLookup Lists'!$E$2:$E$17,0)) -> FALSE
A18: =IF(ISBLANK(B18),"","ICJIA") -> ICJIA | B18: Community-Based Violence Intervention and Prevention (CB-VIP) | C18: 172014 SW | D18: 2117 | E18: Lawrence Hall Youth Services | F18: 43647 | G18: 44012 | H18: 192556 | I18: 2020 | M18: =IF(ISNUMBER(MATCH(E18,_xlfn.VSTACK('VLookup Lists'!$E$2:$E$17,'VLookup Lists'!$H$2:$H$38,'VLookup Lists'!$J$2:$J$8),0)),1,0) -> 0 | N18: =IFERROR(IF(VLOOKUP($D18,'VLookup Lists'!$B$11:$C$29,2,FALSE)="FLIP",1,0),"") | O18: =ISNUMBER(MATCH($E18,'VLookup Lists'!$E$2:$E$17,0)) -> FALSE
A19: =IF(ISBLANK(B19),"","ICJIA") -> ICJIA | B19: Community-Based Violence Intervention and Prevention (CB-VIP) | C19: 172010 SW | D19: 2117 | E19: Northeast DuPage Family and Youth Services | F19: 43647 | G19: 44012 | H19: 132352 | I19: 2020 | M19: =IF(ISNUMBER(MATCH(E19,_xlfn.VSTACK('VLookup Lists'!$E$2:$E$17,'VLookup Lists'!$H$2:$H$38,'VLookup Lists'!$J$2:$J$8),0)),1,0) -> 0 | N19: =IFERROR(IF(VLOOKUP($D19,'VLookup Lists'!$B$11:$C$29,2,FALSE)="FLIP",1,0),"") | O19: =ISNUMBER(MATCH($E19,'VLookup Lists'!$E$2:$E$17,0)) -> FALSE
A20: =IF(ISBLANK(B20),"","ICJIA") -> ICJIA | B20: Community-Based Violence Intervention and Prevention (CB-VIP) | C20: 172011 SW | D20: 2117 | E20: Pilsen Wellness Center, Inc. | F20: 43647 | G20: 44012 | H20: 251072 | I20: 2020 | M20: =IF(ISNUMBER(MATCH(E20,_xlfn.VSTACK('VLookup Lists'!$E$2:$E$17,'VLookup Lists'!$H$2:$H$38,'VLookup Lists'!$J$2:$J$8),0)),1,0) -> 0 | N20: =IFERROR(IF(VLOOKUP($D20,'VLookup Lists'!$B$11:$C$29,2,FALSE)="FLIP",1,0),"") | O20: =ISNUMBER(MATCH($E20,'VLookup Lists'!$E$2:$E$17,0)) -> FALSE
A21: =IF(ISBLANK(B21),"","ICJIA") -> ICJIA | B21: Community-Based Violence Intervention and Prevention (CB-VIP) | C21: 172012 SW | D21: 2117 | E21: Region 1 Planning Council | F21: 43647 | G21: 44012 | H21: 195923 | I21: 2020 | M21: =IF(ISNUMBER(MATCH(E21,_xlfn.VSTACK('VLookup Lists'!$E$2:$E$17,'VLookup Lists'!$H$2:$H$38,'VLookup Lists'!$J$2:$J$8),0)),1,0) -> 0 | N21: =IFERROR(IF(VLOOKUP($D21,'VLookup Lists'!$B$11:$C$29,2,FALSE)="FLIP",1,0),"") | O21: =ISNUMBER(MATCH($E21,'VLookup Lists'!$E$2:$E$17,0)) -> FALSE
A22: =IF(ISBLANK(B22),"","ICJIA") -> ICJIA | B22: Community-Based Violence Intervention and Prevention (CB-VIP) | C22: 172015 SW | D22: 2117 | E22: South Shore Drill Team & Performing Arts Ensemble | F22: 43647 | G22: 44012 | H22: 83195 | I22: 2020 | M22: =IF(ISNUMBER(MATCH(E22,_xlfn.VSTACK('VLookup Lists'!$E$2:$E$17,'VLookup Lists'!$H$2:$H$38,'VLookup Lists'!$J$2:$J$8),0)),1,0) -> 0 | N22: =IFERROR(IF(VLOOKUP($D22,'VLookup Lists'!$B$11:$C$29,2,FALSE)="FLIP",1,0),"") | O22: =ISNUMBER(MATCH($E22,'VLookup Lists'!$E$2:$E$17,0)) -> FALSE
A23: =IF(ISBLANK(B23),"","ICJIA") -> ICJIA | B23: Community-Based Violence Intervention and Prevention (CB-VIP) | C23: 172004 | D23: 2117 | E23: Springfield Urban League, Inc. | F23: 43647 | G23: 44012 | H23: 313943 | I23: 2020 | M23: =IF(ISNUMBER(MATCH(E23,_xlfn.VSTACK('VLookup Lists'!$E$2:$E$17,'VLookup Lists'!$H$2:$H$38,'VLookup Lists'!$J$2:$J$8),0)),1,0) -> 0 | N23: =IFERROR(IF(VLOOKUP($D23,'VLookup Lists'!$B$11:$C$29,2,FALSE)="FLIP",1,0),"") | O23: =ISNUMBER(MATCH($E23,'VLookup Lists'!$E$2:$E$17,0)) -> FALSE
A24: =IF(ISBLANK(B24),"","ICJIA") -> ICJIA | B24: Community-Based Violence Intervention and Prevention (CB-VIP) | C24: 172017 SW | D24: 2117 | E24: UNIVERSAL FAMILY CONNECTION, INC. | F24: 43647 | G24: 44012 | H24: 682382 | I24: 2020 | M24: =IF(ISNUMBER(MATCH(E24,_xlfn.VSTACK('VLookup Lists'!$E$2:$E$17,'VLookup Lists'!$H$2:$H$38,'VLookup Lists'!$J$2:$J$8),0)),1,0) -> 0 | N24: =IFERROR(IF(VLOOKUP($D24,'VLookup Lists'!$B$11:$C$29,2,FALSE)="FLIP",1,0),"") | O24: =ISNUMBER(MATCH($E24,'VLookup Lists'!$E$2:$E$17,0)) -> FALSE
A25: =IF(ISBLANK(B25),"","ICJIA") -> ICJIA | B25: Community-Based Violence Intervention and Prevention (CB-VIP) | D25: 2117 | E25: Alternatives, Inc. | F25: 44013 | G25: 44377 | H25: 317210 | I25: 2021 | M25: =IF(ISNUMBER(MATCH(E25,_xlfn.VSTACK('VLookup Lists'!$E$2:$E$17,'VLookup Lists'!$H$2:$H$38,'VLookup Lists'!$J$2:$J$8),0)),1,0) -> 0 | N25: =IFERROR(IF(VLOOKUP($D25,'VLookup Lists'!$B$11:$C$29,2,FALSE)="FLIP",1,0),"") | O25: =ISNUMBER(MATCH($E25,'VLookup Lists'!$E$2:$E$17,0)) -> FALSE
A26: =IF(ISBLANK(B26),"","ICJIA") -> ICJIA | B26: Community-Based Violence Intervention and Prevention (CB-VIP) | C26: 172101 LM | D26: 2117 | E26: BIG BROTHERS-BIG SISTERS OF METROPOLITAN CHICAGO | F26: 44013 | G26: 44377 | H26: 291368 | I26: 2021 | M26: =IF(ISNUMBER(MATCH(E26,_xlfn.VSTACK('VLookup Lists'!$E$2:$E$17,'VLookup Lists'!$H$2:$H$38,'VLookup Lists'!$J$2:$J$8),0)),1,0) -> 0 | N26: =IFERROR(IF(VLOOKUP($D26,'VLookup Lists'!$B$11:$C$29,2,FALSE)="FLIP",1,0),"") | O26: =ISNUMBER(MATCH($E26,'VLookup Lists'!$E$2:$E$17,0)) -> FALSE
A27: =IF(ISBLANK(B27),"","ICJIA") -> ICJIA | B27: Community-Based Violence Intervention and Prevention (CB-VIP) | D27: 2117 | E27: Bright Star Community Outreach | F27: 44013 | G27: 44377 | H27: 671649 | I27: 2021 | M27: =IF(ISNUMBER(MATCH(E27,_xlfn.VSTACK('VLookup Lists'!$E$2:$E$17,'VLookup Lists'!$H$2:$H$38,'VLookup Lists'!$J$2:$J$8),0)),1,0) -> 0 | N27: =IFERROR(IF(VLOOKUP($D27,'VLookup Lists'!$B$11:$C$29,2,FALSE)="FLIP",1,0),"") | O27: =ISNUMBER(MATCH($E27,'VLookup Lists'!$E$2:$E$17,0)) -> FALSE
A28: =IF(ISBLANK(B28),"","ICJIA") -> ICJIA | B28: Community-Based Violence Intervention and Prevention (CB-VIP) | D28: 2117 | E28: Cabrini Green Legal Aid | F28: 44013 | G28: 44377 | H28: 172781 | I28: 2021 | M28: =IF(ISNUMBER(MATCH(E28,_xlfn.VSTACK('VLookup Lists'!$E$2:$E$17,'VLookup Lists'!$H$2:$H$38,'VLookup Lists'!$J$2:$J$8),0)),1,0) -> 0 | N28: =IFERROR(IF(VLOOKUP($D28,'VLookup Lists'!$B$11:$C$29,2,FALSE)="FLIP",1,0),"") | O28: =ISNUMBER(MATCH($E28,'VLookup Lists'!$E$2:$E$17,0)) -> FALSE
A29: =IF(ISBLANK(B29),"","ICJIA") -> ICJIA | B29: Community-Based Violence Intervention and Prevention (CB-VIP) | D29: 2117 | E29: Catholic Charities of the Archdiocese of Chicago | F29: 44013 | G29: 44377 | H29: 568817 | I29: 2021 | M29: =IF(ISNUMBER(MATCH(E29,_xlfn.VSTACK('VLookup Lists'!$E$2:$E$17,'VLookup Lists'!$H$2:$H$38,'VLookup Lists'!$J$2:$J$8),0)),1,0) -> 0 | N29: =IFERROR(IF(VLOOKUP($D29,'VLookup Lists'!$B$11:$C$29,2,FALSE)="FLIP",1,0),"") | O29: =ISNUMBER(MATCH($E29,'VLookup Lists'!$E$2:$E$17,0)) -> FALSE
A30: =IF(ISBLANK(B30),"","ICJIA") -> ICJIA | B30: Community-Based Violence Intervention and Prevention (CB-VIP) | C30: 172105 LM | D30: 2117 | E30: Children's Home & Aid Society of Illinois dba Brightpoint | F30: 44013 | G30: 44377 | H30: 102173 | I30: 2021 | M30: =IF(ISNUMBER(MATCH(E30,_xlfn.VSTACK('VLookup Lists'!$E$2:$E$17,'VLookup Lists'!$H$2:$H$38,'VLookup Lists'!$J$2:$J$8),0)),1,0) -> 0 | N30: =IFERROR(IF(VLOOKUP($D30,'VLookup Lists'!$B$11:$C$29,2,FALSE)="FLIP",1,0),"") | O30: =ISNUMBER(MATCH($E30,'VLookup Lists'!$E$2:$E$17,0)) -> FALSE
A31: =IF(ISBLANK(B31),"","ICJIA") -> ICJIA | B31: Community-Based Violence Intervention and Prevention (CB-VIP) | D31: 2117 | E31: Gary Comer Youth Center, Inc. | F31: 44013 | G31: 44377 | H31: 807505 | I31: 2021 | M31: =IF(ISNUMBER(MATCH(E31,_xlfn.VSTACK('VLookup Lists'!$E$2:$E$17,'VLookup Lists'!$H$2:$H$38,'VLookup Lists'!$J$2:$J$8),0)),1,0) -> 0 | N31: =IFERROR(IF(VLOOKUP($D31,'VLookup Lists'!$B$11:$C$29,2,FALSE)="FLIP",1,0),"") | O31: =ISNUMBER(MATCH($E31,'VLookup Lists'!$E$2:$E$17,0)) -> FALSE
A32: =IF(ISBLANK(B32),"","ICJIA") -> ICJIA | B32: Community-Based Violence Intervention and Prevention (CB-VIP) | D32: 2117 | E32: Heartland Alliance | F32: 44013 | G32: 44377 | H32: 659942 | I32: 2021 | M32: =IF(ISNUMBER(MATCH(E32,_xlfn.VSTACK('VLookup Lists'!$E$2:$E$17,'VLookup Lists'!$H$2:$H$38,'VLookup Lists'!$J$2:$J$8),0)),1,0) -> 0 | N32: =IFERROR(IF(VLOOKUP($D32,'VLookup Lists'!$B$11:$C$29,2,FALSE)="FLIP",1,0),"") | O32: =ISNUMBER(MATCH($E32,'VLookup Lists'!$E$2:$E$17,0)) -> FALSE
A33: =IF(ISBLANK(B33),"","ICJIA") -> ICJIA | B33: Community-Based Violence Intervention and Prevention (CB-VIP) | D33: 2117 | E33: Illinois Association of Juvenile Justice Councils | F33: 44013 | G33: 44377 | H33: 928239 | I33: 2021 | M33: =IF(ISNUMBER(MATCH(E33,_xlfn.VSTACK('VLookup Lists'!$E$2:$E$17,'VLookup Lists'!$H$2:$H$38,'VLookup Lists'!$J$2:$J$8),0)),1,0) -> 0 | N33: =IFERROR(IF(VLOOKUP($D33,'VLookup Lists'!$B$11:$C$29,2,FALSE)="FLIP",1,0),"") | O33: =ISNUMBER(MATCH($E33,'VLookup Lists'!$E$2:$E$17,0)) -> FALSE
A34: =IF(ISBLANK(B34),"","ICJIA") -> ICJIA | B34: Community-Based Violence Intervention and Prevention (CB-VIP) | D34: 2117 | E34: Lawrence Hall Youth Services | F34: 44013 | G34: 44377 | H34: 192556 | I34: 2021 | M34: =IF(ISNUMBER(MATCH(E34,_xlfn.VSTACK('VLookup Lists'!$E$2:$E$17,'VLookup Lists'!$H$2:$H$38,'VLookup Lists'!$J$2:$J$8),0)),1,0) -> 0 | N34: =IFERROR(IF(VLOOKUP($D34,'VLookup Lists'!$B$11:$C$29,2,FALSE)="FLIP",1,0),"") | O34: =ISNUMBER(MATCH($E34,'VLookup Lists'!$E$2:$E$17,0)) -> FALSE
A35: =IF(ISBLANK(B35),"","ICJIA") -> ICJIA | B35: Community-Based Violence Intervention and Prevention (CB-VIP) | D35: 2117 | E35: Northeast DuPage Family and Youth Services | F35: 44013 | G35: 44377 | H35: 132035 | I35: 2021 | M35: =IF(ISNUMBER(MATCH(E35,_xlfn.VSTACK('VLookup Lists'!$E$2:$E$17,'VLookup Lists'!$H$2:$H$38,'VLookup Lists'!$J$2:$J$8),0)),1,0) -> 0 | N35: =IFERROR(IF(VLOOKUP($D35,'VLookup Lists'!$B$11:$C$29,2,FALSE)="FLIP",1,0),"") | O35: =ISNUMBER(MATCH($E35,'VLookup Lists'!$E$2:$E$17,0)) -> FALSE
A36: =IF(ISBLANK(B36),"","ICJIA") -> ICJIA | B36: Community-Based Violence Intervention and Prevention (CB-VIP) | C36: 172111 LM | D36: 2117 | E36: Pilsen Wellness Center, Inc. | F36: 44013 | G36: 44377 | H36: 251061 | I36: 2021 | M36: =IF(ISNUMBER(MATCH(E36,_xlfn.VSTACK('VLookup Lists'!$E$2:$E$17,'VLookup Lists'!$H$2:$H$38,'VLookup Lists'!$J$2:$J$8),0)),1,0) -> 0 | N36: =IFERROR(IF(VLOOKUP($D36,'VLookup Lists'!$B$11:$C$29,2,FALSE)="FLIP",1,0),"") | O36: =ISNUMBER(MATCH($E36,'VLookup Lists'!$E$2:$E$17,0)) -> FALSE
A37: =IF(ISBLANK(B37),"","ICJIA") -> ICJIA | B37: Community-Based Violence Intervention and Prevention (CB-VIP) | C37: 172112 KE | D37: 2117 | E37: Region 1 Planning Council | F37: 44013 | G37: 44377 | H37: 195923 | I37: 2021 | M37: =IF(ISNUMBER(MATCH(E37,_xlfn.VSTACK('VLookup Lists'!$E$2:$E$17,'VLookup Lists'!$H$2:$H$38,'VLookup Lists'!$J$2:$J$8),0)),1,0) -> 0 | N37: =IFERROR(IF(VLOOKUP($D37,'VLookup Lists'!$B$11:$C$29,2,FALSE)="FLIP",1,0),"") | O37: =ISNUMBER(MATCH($E37,'VLookup Lists'!$E$2:$E$17,0)) -> FALSE
A38: =IF(ISBLANK(B38),"","ICJIA") -> ICJIA | B38: Community-Based Violence Intervention and Prevention (CB-VIP) | C38: 172115 SA | D38: 2117 | E38: South Shore Drill Team & Performing Arts Ensemble | F38: 44013 | G38: 44377 | H38: 83195 | I38: 2021 | M38: =IF(ISNUMBER(MATCH(E38,_xlfn.VSTACK('VLookup Lists'!$E$2:$E$17,'VLookup Lists'!$H$2:$H$38,'VLookup Lists'!$J$2:$J$8),0)),1,0) -> 0 | N38: =IFERROR(IF(VLOOKUP($D38,'VLookup Lists'!$B$11:$C$29,2,FALSE)="FLIP",1,0),"") | O38: =ISNUMBER(MATCH($E38,'VLookup Lists'!$E$2:$E$17,0)) -> FALSE
A39: =IF(ISBLANK(B39),"","ICJIA") -> ICJIA | B39: Community-Based Violence Intervention and Prevention (CB-VIP) | C39: 172113 AB | D39: 2117 | E39: Springfield Urban League, Inc. | F39: 44013 | G39: 44377 | H39: 313943 | I39: 2021 | M39: =IF(ISNUMBER(MATCH(E39,_xlfn.VSTACK('VLookup Lists'!$E$2:$E$17,'VLookup Lists'!$H$2:$H$38,'VLookup Lists'!$J$2:$J$8),0)),1,0) -> 0 | N39: =IFERROR(IF(VLOOKUP($D39,'VLookup Lists'!$B$11:$C$29,2,FALSE)="FLIP",1,0),"") | O39: =ISNUMBER(MATCH($E39,'VLookup Lists'!$E$2:$E$17,0)) -> FALSE
A40: =IF(ISBLANK(B40),"","ICJIA") -> ICJIA | B40: Community-Based Violence Intervention and Prevention (CB-VIP) | D40: 2117 | E40: UNIVERSAL FAMILY CONNECTION, INC. | F40: 44013 | G40: 44377 | H40: 682375 | I40: 2021 | M40: =IF(ISNUMBER(MATCH(E40,_xlfn.VSTACK('VLookup Lists'!$E$2:$E$17,'VLookup Lists'!$H$2:$H$38,'VLookup Lists'!$J$2:$J$8),0)),1,0) -> 0 | N40: =IFERROR(IF(VLOOKUP($D40,'VLookup Lists'!$B$11:$C$29,2,FALSE)="FLIP",1,0),"") | O40: =ISNUMBER(MATCH($E40,'VLookup Lists'!$E$2:$E$17,0)) -> FALSE
...

Sheet Master List
A1: {=_xlfn._xlws.FILTER(_xlfn.VSTACK(OFVP!A1:O9496,ICJIA!A2:O9583),_xlfn.VSTACK(OFVP!B1:B9496,ICJIA!B2:B9583)<>"")} -> Source | B1: Grant Type | C1: Award ID | D1: CSFA | E1: Grantee Name | F1: Start Date | G1: End Date | H1: Award Amount | I1: Fiscal Year | J1: Chicago/Greater Illinois | K1: County | L1: Community Area | M1: CVI | N1: FLIP | O1: CP4P
A2: OFVP | B2: TA Services Violence Prevention | C2: 0 | D2: 2771 | E2: Acclivus, Inc. | F2: 0 | G2: 45930 | H2: 150000 | I2: 2022 | J2: Chicago | K2: Cook | L2: z TTAS - Chicago | M2: 1 | N2: 0 | O2: FALSE
A3: OFVP | B3: TA Services Violence Prevention | C3: 0 | D3: 2771 | E3: Metropolitan Family Services | F3: 0 | G3: 45565 | H3: 188061 | I3: 2022 | J3: Chicago | K3: Cook | L3: z TTAS - Chicago | M3: 1 | N3: 0 | O3: TRUE
A4: OFVP | B4: TA Services Violence Prevention | C4: 0 | D4: 2771 | E4: UNIVERSAL FAMILY CONNECTION | F4: 0 | G4: 45344 | H4: 159600 | I4: 2022 | J4: Chicago | K4: Cook | L4: z TTAS - Chicago | M4: 0 | N4: 0 | O4: FALSE
A5: OFVP | B5: TA Services Youth Development | C5: 0 | D5: 2772 | E5: BLACK COMMUNITY PROVIDER | F5: 0 | G5: 45565 | H5: 145486 | I5: 2022 | J5: Chicago | K5: Cook | L5: z TTAS - Chicago | M5: 0 | N5: 0 | O5: FALSE
A6: OFVP | B6: TA Services Youth Development | C6: 0 | D6: 2772 | E6: Metropolitan Family Services | F6: 0 | G6: 45565 | H6: 203463 | I6: 2022 | J6: Chicago | K6: Cook | L6: z TTAS - Chicago | M6: 1 | N6: 0 | O6: TRUE
A7: OFVP | B7: TA Services Youth Development | C7: 0 | D7: 2772 | E7: Prevention First, Inc | F7: 0 | G7: 45565 | H7: 168150 | I7: 2022 | J7: Chicago | K7: Cook | L7: z TTAS - Chicago | M7: 0 | N7: 0 | O7: FALSE
A8: OFVP | B8: Chicago Conveners | C8: 0 | D8: 2773 | E8: Lawrence Hall Youth Services | F8: 0 | G8: 45747 | H8: 25000 | I8: 2022 | J8: Chicago | K8: Cook | L8: South Shore | M8: 0 | N8: 0 | O8: FALSE
A9: OFVP | B9: Chicago Conveners | C9: 0 | D9: 2773 | E9: UNIVERSAL FAMILY CONNECTION | F9: 0 | G9: 45747 | H9: 24999.95 | I9: 2022 | J9: Chicago | K9: Cook | L9: Auburn Gresham | M9: 0 | N9: 0 | O9: FALSE
A10: OFVP | B10: Chicago Conveners | C10: 0 | D10: 2773 | E10: UNIVERSAL FAMILY CONNECTION | F10: 0 | G10: 45747 | H10: 24999.95 | I10: 2022 | J10: Chicago | K10: Cook | L10: Englewood | M10: 0 | N10: 0 | O10: FALSE
A11: OFVP | B11: Chicago Conveners | C11: 0 | D11: 2773 | E11: WHAT ABOUT US CHARITABLE | F11: 0 | G11: 45747 | H11: 25000 | I11: 2022 | J11: Chicago | K11: Cook | L11: Austin | M11: 0 | N11: 0 | O11: FALSE
A12: OFVP | B12: Chicago Conveners | C12: 0 | D12: 2773 | E12: YMCA OF METROPOLITAN CHICAGO | F12: 0 | G12: 45747 | H12: 24075 | I12: 2022 | J12: Chicago | K12: Cook | L12: Chicago Lawn | M12: 1 | N12: 0 | O12: FALSE
A13: OFVP | B13: Chicago Conveners | C13: 0 | D13: 2773 | E13: YMCA OF METROPOLITAN CHICAGO | F13: 0 | G13: 45747 | H13: 24075 | I13: 2022 | J13: Chicago | K13: Cook | L13: East Garfield Park | M13: 1 | N13: 0 | O13: FALSE
... A1584: OFVP | B1584: Back To Our Future | C1584: 0 | D1584: 3621 | E1584: Chicago Public Schools | F1584: 0 | G1584: 0 | H1584: 2000000 | I1584: 2026 | J1584: Chicago | K1584: Cook | L1584: 3621 Chicago Only | M1584: 0 | N1584: 0 | O1584: FALSE
A1585: ICJIA | B1585: Community-based Violence Intervention & Prevention (Fed) | C1585: 662314 JES | D1585: 3380 | E1585: Angel of God Resource Center, Inc. | F1585: 45566 | G1585: 45930 | H1585: 300000 | I1585: 2025 | J1585: 0 | K1585: 0 | L1585: 0 | M1585: 0 | O1585: FALSE
A1586: ICJIA | B1586: Community-based Violence Intervention & Prevention (Fed) | C1586: 662315 JES | D1586: 3380 | E1586: Breakthrough Urban Ministries | F1586: 45566 | G1586: 45930 | H1586: 128577 | I1586: 2025 | J1586: 0 | K1586: 0 | L1586: 0 | M1586: 1 | O1586: TRUE
A1587: ICJIA | B1587: Community-based Violence Intervention & Prevention (Fed) | C1587: 662313 JES | D1587: 3380 | E1587: BUILD Inc. | F1587: 45566 | G1587: 45930 | H1587: 260640 | I1587: 2025 | J1587: 0 | K1587: 0 | L1587: 0 | M1587: 1 | O1587: FALSE
A1588: ICJIA | B1588: Community-based Violence Intervention & Prevention (Fed) | C1588: 662310 JES | D1588: 3380 | E1588: Lawndale Christian Legal Center | F1588: 45474 | G1588: 45838 | H1588: 100000 | I1588: 2025 | J1588: 0 | K1588: 0 | L1588: 0 | M1588: 0 | O1588: FALSE
A1589: ICJIA | B1589: Community-based Violence Intervention & Prevention (Fed) | C1589: 662311 JES | D1589: 3380 | E1589: New Eclipse Community Alliance | F1589: 45566 | G1589: 45930 | H1589: 614014 | I1589: 2025 | J1589: 0 | K1589: 0 | L1589: 0 | M1589: 0 | O1589: FALSE
A1590: ICJIA | B1590: Community-based Violence Intervention & Prevention (Fed) | C1590: 662312 JS | D1590: 3380 | E1590: Roseland Ceasefire Project Inc. | F1590: 45474 | G1590: 45838 | H1590: 177455 | I1590: 2025 | J1590: 0 | K1590: 0 | L1590: 0 | M1590: 1 | O1590: FALSE
A1591: ICJIA | B1591: Community-based Violence Intervention & Prevention (Fed) | C1591: 662316 JES | D1591: 3380 | E1591: Southwest Organizing Project (SWOP) | F1591: 45566 | G1591: 45930 | H1591: 214461 | I1591: 2025 | J1591: 0 | K1591: 0 | L1591: 0 | M1591: 1 | O1591: TRUE
A1592: ICJIA | B1592: Community-Based Violence Intervention and Prevention (CB-VIP) | C1592: 172000 SW | D1592: 2117 | E1592: Alternatives, Inc. | F1592: 43647 | G1592: 44012 | H1592: 317210 | I1592: 2020 | J1592: 0 | K1592: 0 | L1592: 0 | M1592: 0 | O1592: FALSE
A1593: ICJIA | B1593: Community-Based Violence Intervention and Prevention (CB-VIP) | C1593: 172001 | D1593: 2117 | E1593: BIG BROTHERS-BIG SISTERS OF METROPOLITAN CHICAGO | F1593: 43647 | G1593: 44012 | H1593: 291588 | I1593: 2020 | J1593: 0 | K1593: 0 | L1593: 0 | M1593: 0 | O1593: FALSE
A1594: ICJIA | B1594: Community-Based Violence Intervention and Prevention (CB-VIP) | C1594: 172002 STB | D1594: 2117 | E1594: Bright Star Community Outreach | F1594: 43647 | G1594: 44012 | H1594: 690921 | I1594: 2020 | J1594: 0 | K1594: 0 | L1594: 0 | M1594: 0 | O1594: FALSE
A1595: ICJIA | B1595: Community-Based Violence Intervention and Prevention (CB-VIP) | C1595: 172003 STB | D1595: 2117 | E1595: Cabrini Green Legal AId | F1595: 43647 | G1595: 44012 | H1595: 173418 | I1595: 2020 | J1595: 0 | K1595: 0 | L1595: 0 | M1595: 0 | O1595: FALSE
A1596: ICJIA | B1596: Community-Based Violence Intervention and Prevention (CB-VIP) | C1596: 172004 | D1596: 2117 | E1596: Catholic Charities of the Archdiocese of Chicago | F1596: 43647 | G1596: 44012 | H1596: 569782 | I1596: 2020 | J1596: 0 | K1596: 0 | L1596: 0 | M1596: 0 | O1596: FALSE
A1597: ICJIA | B1597: Community-Based Violence Intervention and Prevention (CB-VIP) | C1597: 172005 | D1597: 2117 | E1597: Children's Home & Aid Society of Illinois dba Brightpoint | F1597: 43647 | G1597: 44012 | H1597: 102173 | I1597: 2020 | J1597: 0 | K1597: 0 | L1597: 0 | M1597: 0 | O1597: FALSE
